Workbook

Sheet Codebook
A1: Asset | B1: Ticker | C1: Type | D1: Field
A2: Anglo American plc | B2: AAL.L | C2: Equity | D2: Mining
A3: Barclays PLC | B3: BARC.L | C3: Equity | D3: Banks
A4: Hiscox Ltd | B4: HSX.L | C4: Equity | D4: Non-life Insurance
A5: Marks and Spencer Group plc | B5: MKS.L | C5: Equity | D5: Food & drug retailing
A6: National Grid plc | B6: NG.L | C6: Equity | D6: Multiline utilities
A7: Unilever PLC | B7: ULVR.L | C7: Equity | D7: Personal goods
A8: Vanguard U.K. Gilt UCITS ETF | B8: VGOV.L | C8: ETF | D8: Gilts
A9: iShares Physical Gold ETC | B9: SGLN.L | C9: ETC | D9: Gold

Sheet Asset Returns
B1: AAL.L | C1: AAL.L | D1: BARC.L | E1: BARC.L | F1: HSX.L | G1: HSX.L | H1: MKS.L | I1: MKS.L | J1: NG.L | K1: NG.L | L1: ULVR.L | M1: ULVR.L | N1: VGOV.L | O1: VGOV.L | P1: SGLN.L | Q1: SGLN.L
A2: Date | B2: Simple Return | C2: Log Return | D2: Simple Return2 | E2: Log Return3 | F2: Simple Return4 | G2: Log Return5 | H2: Simple Return6 | I2: Log Return7 | J2: Simple Return8 | K2: Log Return9 | L2: Simple Return10 | M2: Log Return11 | N2: Simple Return12 | O2: Log Return13 | P2: Simple Return14 | Q2: Log Return15
A3: 2016-08-17 00:00:00+01:00 | B3: - | C3: - | D3: - | E3: - | F3: - | G3: - | H3: - | I3: - | J3: - | K3: - | L3: - | M3: - | N3: - | O3: - | P3: - | Q3: -
A4: 2016-08-18 00:00:00+01:00 | B4: =('AAL L'!F3-'AAL L'!F2)/'AAL L'!F2 -> 0.016518396 | C4: =LN('AAL L'!F3/'AAL L'!F2) -> 0.016383452 | D4: =('BARC L'!F3-'BARC L'!F2)/'BARC L'!F2 -> 0.0031219123 | E4: =LN('BARC L'!F3/'BARC L'!F2) -> 0.0031170493 | F4: =('HSX L'!F3-'HSX L'!F2)/'HSX L'!F2 -> 0 | G4: =LN('HSX L'!F3/'HSX L'!F2) -> 0 | H4: =('MKS L'!F3-'MKS L'!F2)/'MKS L'!F2 -> 0.0083230505 | I4: =LN('MKS L'!F3/'MKS L'!F2) -> 0.008288605 | J4: =('NG L'!F3-'NG L'!F2)/'NG L'!F2 -> 0.010747786 | K4: =LN('NG L'!F3/'NG L'!F2) -> 0.010690439 | L4: =('ULVR L'!F3-'ULVR L'!F2)/'ULVR L'!F2 -> -0.0042891379 | M4: =LN('ULVR L'!F3/'ULVR L'!F2) -> -0.0042983627 | N4: =('VGOV L'!F3-'VGOV L'!F2)/'VGOV L'!F2 -> 0.0034051323 | O4: =LN('VGOV L'!F3/'VGOV L'!F2) -> 0.0033993479 | P4: =('SGLN L'!F3-'SGLN L'!F2)/'SGLN L'!F2 -> -0.0079578844 | Q4: =LN('SGLN L'!F3/'SGLN L'!F2) -> -0.0079897174
A5: 2016-08-19 00:00:00+01:00 | B5: =('AAL L'!F4-'AAL L'!F3)/'AAL L'!F3 -> -0.011363578 | C5: =LN('AAL L'!F4/'AAL L'!F3) -> -0.011428637 | D5: =('BARC L'!F4-'BARC L'!F3)/'BARC L'!F3 -> -0.0018672035 | E5: =LN('BARC L'!F4/'BARC L'!F3) -> -0.0018689489 | F5: =('HSX L'!F4-'HSX L'!F3)/'HSX L'!F3 -> -0.011256811 | G5: =LN('HSX L'!F4/'HSX L'!F3) -> -0.011320648 | H5: =('MKS L'!F4-'MKS L'!F3)/'MKS L'!F3 -> -0.0047170152 | I5: =LN('MKS L'!F4/'MKS L'!F3) -> -0.0047281754 | J5: =('NG L'!F4-'NG L'!F3)/'NG L'!F3 -> -0.00092475164 | K5: =LN('NG L'!F4/'NG L'!F3) -> -0.00092517948 | L5: =('ULVR L'!F4-'ULVR L'!F3)/'ULVR L'!F3 -> 0.002223264 | M5: =LN('ULVR L'!F4/'ULVR L'!F3) -> 0.0022207962 | N5: =('VGOV L'!F4-'VGOV L'!F3)/'VGOV L'!F3 -> -0.0081831046 | O5: =LN('VGOV L'!F4/'VGOV L'!F3) -> -0.00821677 | P5: =('SGLN L'!F4-'SGLN L'!F3)/'SGLN L'!F3 -> 0.0020979884 | Q5: =LN('SGLN L'!F4/'SGLN L'!F3) -> 0.0020957907
A6: 2016-08-22 00:00:00+01:00 | B6: =('AAL L'!F5-'AAL L'!F4)/'AAL L'!F4 -> -0.040229929 | C6: =LN('AAL L'!F5/'AAL L'!F4) -> -0.041061532 | D6: =('BARC L'!F5-'BARC L'!F4)/'BARC L'!F4 -> -0.0018707919 | E6: =LN('BARC L'!F5/'BARC L'!F4) -> -0.001872544 | F6: =('HSX L'!F5-'HSX L'!F4)/'HSX L'!F4 -> 0.0037949898 | G6: =LN('HSX L'!F5/'HSX L'!F4) -> 0.003787807 | H6: =('MKS L'!F5-'MKS L'!F4)/'MKS L'!F4 -> -0.002073105 | I6: =LN('MKS L'!F5/'MKS L'!F4) -> -0.0020752568 | J6: =('NG L'!F5-'NG L'!F4)/'NG L'!F4 -> 0.0004628038 | K6: =LN('NG L'!F5/'NG L'!F4) -> 0.00046269674 | L6: =('ULVR L'!F5-'ULVR L'!F4)/'ULVR L'!F4 -> -0.011368364 | M6: =LN('ULVR L'!F5/'ULVR L'!F4) -> -0.011433478 | N6: =('VGOV L'!F5-'VGOV L'!F4)/'VGOV L'!F4 -> 0.0067038465 | O6: =LN('VGOV L'!F5/'VGOV L'!F4) -> 0.0066814757 | P6: =('SGLN L'!F5-'SGLN L'!F4)/'SGLN L'!F4 -> -0.0093596059 | Q6: =LN('SGLN L'!F5/'SGLN L'!F4) -> -0.0094036823
A7: 2016-08-23 00:00:00+01:00 | B7: =('AAL L'!F6-'AAL L'!F5)/'AAL L'!F5 -> 0.049221516 | C7: =LN('AAL L'!F6/'AAL L'!F5) -> 0.048048476 | D7: =('BARC L'!F6-'BARC L'!F5)/'BARC L'!F5 -> 0.028428324 | E7: =LN('BARC L'!F6/'BARC L'!F5) -> 0.028031737 | F7: =('HSX L'!F6-'HSX L'!F5)/'HSX L'!F5 -> 0.00094527619 | G7: =LN('HSX L'!F6/'HSX L'!F5) -> 0.00094482969 | H7: =('MKS L'!F6-'MKS L'!F5)/'MKS L'!F5 -> 0.00029671845 | I7: =LN('MKS L'!F6/'MKS L'!F5) -> 0.00029667444 | J7: =('NG L'!F6-'NG L'!F5)/'NG L'!F5 -> -0.0046254808 | K7: =LN('NG L'!F6/'NG L'!F5) -> -0.0046362115 | L7: =('ULVR L'!F6-'ULVR L'!F5)/'ULVR L'!F5 -> -0.0007012565 | M7: =LN('ULVR L'!F6/'ULVR L'!F5) -> -0.0007015025 | N7: =('VGOV L'!F6-'VGOV L'!F5)/'VGOV L'!F5 -> 0.0046098156 | O7: =LN('VGOV L'!F6/'VGOV L'!F5) -> 0.004599223 | P7: =('SGLN L'!F6-'SGLN L'!F5)/'SGLN L'!F5 -> -0.0037294878 | Q7: =LN('SGLN L'!F6/'SGLN L'!F5) -> -0.0037364597
A8: 2016-08-24 00:00:00+01:00 | B8: =('AAL L'!F7-'AAL L'!F6)/'AAL L'!F6 -> -0.031389147 | C8: =LN('AAL L'!F7/'AAL L'!F6) -> -0.031892345 | D8: =('BARC L'!F7-'BARC L'!F6)/'BARC L'!F6 -> 0.011846916 | E8: =LN('BARC L'!F7/'BARC L'!F6) -> 0.01177729 | F8: =('HSX L'!F7-'HSX L'!F6)/'HSX L'!F6 -> 0 | G8: =LN('HSX L'!F7/'HSX L'!F6) -> 0 | H8: =('MKS L'!F7-'MKS L'!F6)/'MKS L'!F6 -> 0.0029673559 | I8: =LN('MKS L'!F7/'MKS L'!F6) -> 0.002962962 | J8: =('NG L'!F7-'NG L'!F6)/'NG L'!F6 -> -0.011616916 | K8: =LN('NG L'!F7/'NG L'!F6) -> -0.011684919 | L8: =('ULVR L'!F7-'ULVR L'!F6)/'ULVR L'!F6 -> -0.010244218 | M8: =LN('ULVR L'!F7/'ULVR L'!F6) -> -0.010297051 | N8: =('VGOV L'!F7-'VGOV L'!F6)/'VGOV L'!F6 -> 0.0013262014 | O8: =LN('VGOV L'!F7/'VGOV L'!F6) -> 0.0013253228 | P8: =('SGLN L'!F7-'SGLN L'!F6)/'SGLN L'!F6 -> -0.011729473 | Q8: =LN('SGLN L'!F7/'SGLN L'!F6) -> -0.011798806
A9: 2016-08-25 00:00:00+01:00 | B9: =('AAL L'!F8-'AAL L'!F7)/'AAL L'!F7 -> -0.010605701 | C9: =LN('AAL L'!F8/'AAL L'!F7) -> -0.010662343 | D9: =('BARC L'!F8-'BARC L'!F7)/'BARC L'!F7 -> -0.013208954 | E9: =LN('BARC L'!F8/'BARC L'!F7) -> -0.013296968 | F9: =('HSX L'!F8-'HSX L'!F7)/'HSX L'!F7 -> -0.0047214554 | G9: =LN('HSX L'!F8/'HSX L'!F7) -> -0.0047326367 | H9: =('MKS L'!F8-'MKS L'!F7)/'MKS L'!F7 -> 0.026331629 | I9: =LN('MKS L'!F8/'MKS L'!F7) -> 0.025990919 | J9: =('NG L'!F8-'NG L'!F7)/'NG L'!F7 -> 0.010813263 | K9: =LN('NG L'!F8/'NG L'!F7) -> 0.010755217 | L9: =('ULVR L'!F8-'ULVR L'!F7)/'ULVR L'!F7 -> 0.0093579304 | M9: =LN('ULVR L'!F8/'ULVR L'!F7) -> 0.0093144163 | N9: =('VGOV L'!F8-'VGOV L'!F7)/'VGOV L'!F7 -> -0.00091677235 | O9: =LN('VGOV L'!F8/'VGOV L'!F7) -> -0.00091719284 | P9: =('SGLN L'!F8-'SGLN L'!F7)/'SGLN L'!F7 -> -0.0011363636 | Q9: =LN('SGLN L'!F8/'SGLN L'!F7) -> -0.0011370098
A10: 2016-08-26 00:00:00+01:00 | B10: =('AAL L'!F9-'AAL L'!F8)/'AAL L'!F8 -> 0.022510468 | C10: =LN('AAL L'!F9/'AAL L'!F8) -> 0.022260847 | D10: =('BARC L'!F9-'BARC L'!F8)/'BARC L'!F8 -> 0.010039301 | E10: =LN('BARC L'!F9/'BARC L'!F8) -> 0.0099892419 | F10: =('HSX L'!F9-'HSX L'!F8)/'HSX L'!F8 -> -0.0018974949 | G10: =LN('HSX L'!F9/'HSX L'!F8) -> -0.0018992974 | H10: =('MKS L'!F9-'MKS L'!F8)/'MKS L'!F8 -> -0.0054772706 | I10: =LN('MKS L'!F9/'MKS L'!F8) -> -0.0054923258 | J10: =('NG L'!F9-'NG L'!F8)/'NG L'!F8 -> -0.00046527627 | K10: =LN('NG L'!F9/'NG L'!F8) -> -0.00046538455 | L10: =('ULVR L'!F9-'ULVR L'!F8)/'ULVR L'!F8 -> 0.0026686099 | M10: =LN('ULVR L'!F9/'ULVR L'!F8) -> 0.0026650554 | N10: =('VGOV L'!F9-'VGOV L'!F8)/'VGOV L'!F8 -> 0.0022424876 | O10: =LN('VGOV L'!F9/'VGOV L'!F8) -> 0.002239977 | P10: =('SGLN L'!F9-'SGLN L'!F8)/'SGLN L'!F8 -> 0.006573126 | Q10: =LN('SGLN L'!F9/'SGLN L'!F8) -> 0.0065516172
A11: 2016-08-30 00:00:00+01:00 | B11: =('AAL L'!F10-'AAL L'!F9)/'AAL L'!F9 -> -0.047757581 | C11: =LN('AAL L'!F10/'AAL L'!F9) -> -0.048935635 | D11: =('BARC L'!F10-'BARC L'!F9)/'BARC L'!F9 -> 0.018976117 | E11: =LN('BARC L'!F10/'BARC L'!F9) -> 0.018798316 | F11: =('HSX L'!F10-'HSX L'!F9)/'HSX L'!F9 -> 0.0019011022 | G11: =LN('HSX L'!F10/'HSX L'!F9) -> 0.0018992974 | H11: =('MKS L'!F10-'MKS L'!F9)/'MKS L'!F9 -> -0.011594283 | I11: =LN('MKS L'!F10/'MKS L'!F9) -> -0.011662021 | J11: =('NG L'!F10-'NG L'!F9)/'NG L'!F9 -> -0.020009073 | K11: =LN('NG L'!F10/'NG L'!F9) -> -0.020211966 | L11: =('ULVR L'!F10-'ULVR L'!F9)/'ULVR L'!F9 -> 0.00014012663 | M11: =LN('ULVR L'!F10/'ULVR L'!F9) -> 0.00014011681 | N11: =('VGOV L'!F10-'VGOV L'!F9)/'VGOV L'!F9 -> 0.00071179751 | O11: =LN('VGOV L'!F10/'VGOV L'!F9) -> 0.0007115443 | P11: =('SGLN L'!F10-'SGLN L'!F9)/'SGLN L'!F9 -> -0.0022604546 | Q11: =LN('SGLN L'!F10/'SGLN L'!F9) -> -0.0022630133
A12: 2016-08-31 00:00:00+01:00 | B12: =('AAL L'!F11-'AAL L'!F10)/'AAL L'!F10 -> -0.046116194 | C12: =LN('AAL L'!F11/'AAL L'!F10) -> -0.047213412 | D12: =('BARC L'!F11-'BARC L'!F10)/'BARC L'!F10 -> 0.01832676 | E12: =LN('BARC L'!F11/'BARC L'!F10) -> 0.018160849 | F12: =('HSX L'!F11-'HSX L'!F10)/'HSX L'!F10 -> -0.0094875905 | G12: =LN('HSX L'!F11/'HSX L'!F10) -> -0.0095328844 | H12: =('MKS L'!F11-'MKS L'!F10)/'MKS L'!F10 -> 0.010850268 | I12: =LN('MKS L'!F11/'MKS L'!F10) -> 0.010791826 | J12: =('NG L'!F11-'NG L'!F10)/'NG L'!F10 -> -0.0061728257 | K12: =LN('NG L'!F11/'NG L'!F10) -> -0.0061919563 | L12: =('ULVR L'!F11-'ULVR L'!F10)/'ULVR L'!F10 -> -0.011345971 | M12: =LN('ULVR L'!F11/'ULVR L'!F10) -> -0.011410828 | N12: =('VGOV L'!F11-'VGOV L'!F10)/'VGOV L'!F10 -> -0.003556848 | O12: =LN('VGOV L'!F11/'VGOV L'!F10) -> -0.0035631887 | P12: =('SGLN L'!F11-'SGLN L'!F10)/'SGLN L'!F10 -> -0.010195091 | Q12: =LN('SGLN L'!F11/'SGLN L'!F10) -> -0.010247417
A13: 2016-09-01 00:00:00+01:00 | B13: =('AAL L'!F12-'AAL L'!F11)/'AAL L'!F11 -> 0.01141322 | C13: =LN('AAL L'!F12/'AAL L'!F11) -> 0.011348581 | D13: =('BARC L'!F12-'BARC L'!F11)/'BARC L'!F11 -> -0.0040638469 | E13: =LN('BARC L'!F12/'BARC L'!F11) -> -0.0040721268 | F13: =('HSX L'!F12-'HSX L'!F11)/'HSX L'!F11 -> 0.0047890578 | G13: =LN('HSX L'!F12/'HSX L'!F11) -> 0.0047776267 | H13: =('MKS L'!F12-'MKS L'!F11)/'MKS L'!F11 -> 0.0052220397 | I13: =LN('MKS L'!F12/'MKS L'!F11) -> 0.0052084522 | J13: =('NG L'!F12-'NG L'!F11)/'NG L'!F11 -> -0.0057334337 | K13: =LN('NG L'!F12/'NG L'!F11) -> -0.0057499329 | L13: =('ULVR L'!F12-'ULVR L'!F11)/'ULVR L'!F11 -> -0.00042501484 | M13: =LN('ULVR L'!F12/'ULVR L'!F11) -> -0.00042510518 | N13: =('VGOV L'!F12-'VGOV L'!F11)/'VGOV L'!F11 -> -0.0013258813 | O13: =LN('VGOV L'!F12/'VGOV L'!F11) -> -0.0013267611 | P13: =('SGLN L'!F12-'SGLN L'!F11)/'SGLN L'!F11 -> -0.0092828077 | Q13: =LN('SGLN L'!F12/'SGLN L'!F11) -> -0.0093261615
A14: 2016-09-02 00:00:00+01:00 | B14: =('AAL L'!F13-'AAL L'!F12)/'AAL L'!F12 -> 0.024470707 | C14: =LN('AAL L'!F13/'AAL L'!F12) -> 0.024176096 | D14: =('BARC L'!F13-'BARC L'!F12)/'BARC L'!F12 -> 0.016030512 | E14: =LN('BARC L'!F13/'BARC L'!F12) -> 0.01590338 | F14: =('HSX L'!F13-'HSX L'!F12)/'HSX L'!F12 -> 0.029552061 | G14: =LN('HSX L'!F13/'HSX L'!F12) -> 0.029123816 | H14: =('MKS L'!F13-'MKS L'!F12)/'MKS L'!F12 -> 0.021933731 | I14: =LN('MKS L'!F13/'MKS L'!F12) -> 0.021696647 | J14: =('NG L'!F13-'NG L'!F12)/'NG L'!F12 -> 0.028832261 | K14: =LN('NG L'!F13/'NG L'!F12) -> 0.028424432 | L14: =('ULVR L'!F13-'ULVR L'!F12)/'ULVR L'!F12 -> 0.038412298 | M14: =LN('ULVR L'!F13/'ULVR L'!F12) -> 0.03769291 | N14: =('VGOV L'!F13-'VGOV L'!F12)/'VGOV L'!F12 -> -0.0074569681 | O14: =LN('VGOV L'!F13/'VGOV L'!F12) -> -0.0074849103 | P14: =('SGLN L'!F13-'SGLN L'!F12)/'SGLN L'!F12 -> 0.004492363 | Q14: =LN('SGLN L'!F13/'SGLN L'!F12) -> 0.0044823024
A15: 2016-09-05 00:00:00+01:00 | B15: =('AAL L'!F14-'AAL L'!F13)/'AAL L'!F13 -> 0.0074256116 | C15: =LN('AAL L'!F14/'AAL L'!F13) -> 0.0073981774 | D15: =('BARC L'!F14-'BARC L'!F13)/'BARC L'!F13 -> -0.0060244258 | E15: =LN('BARC L'!F14/'BARC L'!F13) -> -0.0060426459 | F15: =('HSX L'!F14-'HSX L'!F13)/'HSX L'!F13 -> -0.0092592991 | G15: =LN('HSX L'!F14/'HSX L'!F13) -> -0.0093024329 | H15: =('MKS L'!F14-'MKS L'!F13)/'MKS L'!F13 -> -0.013837893 | I15: =LN('MKS L'!F14/'MKS L'!F13) -> -0.013934529 | J15: =('NG L'!F14-'NG L'!F13)/'NG L'!F13 -> 0.0084068152 | K15: =LN('NG L'!F14/'NG L'!F13) -> 0.0083716747 | L15: =('ULVR L'!F14-'ULVR L'!F13)/'ULVR L'!F13 -> -0.0036854531 | M15: =LN('ULVR L'!F14/'ULVR L'!F13) -> -0.0036922611 | N15: =('VGOV L'!F14-'VGOV L'!F13)/'VGOV L'!F13 -> 0.0025731478 | O15: =LN('VGOV L'!F14/'VGOV L'!F13) -> 0.0025698429 | P15: =('SGLN L'!F14-'SGLN L'!F13)/'SGLN L'!F13 -> 0.0054945055 | Q15: =LN('SGLN L'!F14/'SGLN L'!F13) -> 0.0054794658
... A2527: 2026-08-14 00:00:00+01:00 | B2527: =('AAL L'!F2526-'AAL L'!F2525)/'AAL L'!F2525 -> -0.01660281 | C2527: =LN('AAL L'!F2526/'AAL L'!F2525) -> -0.016742181 | D2527: =('BARC L'!F2526-'BARC L'!F2525)/'BARC L'!F2525 -> -0.009798224 | E2527: =LN('BARC L'!F2526/'BARC L'!F2525) -> -0.0098465425 | F2527: =('HSX L'!F2526-'HSX L'!F2525)/'HSX L'!F2525 -> 0.0056022409 | G2527: =LN('HSX L'!F2526/'HSX L'!F2525) -> 0.0055866067 | H2527: =('MKS L'!F2526-'MKS L'!F2525)/'MKS L'!F2525 -> -0.018428492 | I2527: =LN('MKS L'!F2526/'MKS L'!F2525) -> -0.018600412 | J2527: =('NG L'!F2526-'NG L'!F2525)/'NG L'!F2525 -> -0.0058309038 | K2527: =LN('NG L'!F2526/'NG L'!F2525) -> -0.0058479699 | L2527: =('ULVR L'!F2526-'ULVR L'!F2525)/'ULVR L'!F2525 -> -0.008426056 | M2527: =LN('ULVR L'!F2526/'ULVR L'!F2525) -> -0.0084617558 | N2527: =('VGOV L'!F2526-'VGOV L'!F2525)/'VGOV L'!F2525 -> -0.0025879892 | O2527: =LN('VGOV L'!F2526/'VGOV L'!F2525) -> -0.0025913438 | P2527: =('SGLN L'!F2526-'SGLN L'!F2525)/'SGLN L'!F2525 -> 0.0025530557 | Q2527: =LN('SGLN L'!F2526/'SGLN L'!F2525) -> 0.0025498022
A2528: 2026-08-17 00:00:00+01:00 | B2528: =('AAL L'!F2527-'AAL L'!F2526)/'AAL L'!F2526 -> 0.02025974 | C2528: =LN('AAL L'!F2527/'AAL L'!F2526) -> 0.020057242 | F2528: =('HSX L'!F2527-'HSX L'!F2526)/'HSX L'!F2526 -> 0.0050139276 | G2528: =LN('HSX L'!F2527/'HSX L'!F2526) -> 0.0050013997 | H2528: =('MKS L'!F2527-'MKS L'!F2526)/'MKS L'!F2526 -> -0.0049543518 | I2528: =LN('MKS L'!F2527/'MKS L'!F2526) -> -0.0049666652 | J2528: =('NG L'!F2527-'NG L'!F2526)/'NG L'!F2526 -> -0.0033514872 | K2528: =LN('NG L'!F2527/'NG L'!F2526) -> -0.003357116 | L2528: =('ULVR L'!F2527-'ULVR L'!F2526)/'ULVR L'!F2526 -> -0.016777427 | M2528: =LN('ULVR L'!F2527/'ULVR L'!F2526) -> -0.016919762 | P2528: =('SGLN L'!F2527-'SGLN L'!F2526)/'SGLN L'!F2526 -> 0.0071621837 | Q2528: =LN('SGLN L'!F2527/'SGLN L'!F2526) -> 0.007136657

Sheet Average Returns
A1: Asset | B1: Ticker | C1: Average Daily Return | D1: Average Daily Log Return | E1: Average Annualised Return | F1: Average Annualised Log Return
A2: Anglo American plc | B2: AAL.L | C2: =AVERAGE('Asset Returns'!B4:B2528) -> 0.00092519354 | D2: =AVERAGE('Asset Returns'!C4:C2528) -> 0.0006102083 | E2: =(1+C2)^252-1 -> 0.26243322 | F2: =D2*252 -> 0.15377249
A3: Barclays PLC | B3: BARC.L | C3: =AVERAGE('Asset Returns'!D4:D2528) -> 0.00068419474 | D3: =AVERAGE('Asset Returns'!E4:E2528) -> 0.00046416876 | E3: =(1+C3)^252-1 -> 0.18810324 | F3: =D3*252 -> 0.11697053
A4: Hiscox Ltd | B4: HSX.L | C4: =AVERAGE('Asset Returns'!F4:F2528) -> 0.00037999759 | D4: =AVERAGE('Asset Returns'!G4:G2528) -> 0.00020916851 | E4: =(1+C4)^252-1 -> 0.10047423 | F4: =D4*252 -> 0.052710464
A5: Marks and Spencer Group plc | B5: MKS.L | C5: =AVERAGE('Asset Returns'!H4:H2528) -> 0.00033511533 | D5: =AVERAGE('Asset Returns'!I4:I2528) -> 7.1372015e-05 | E5: =(1+C5)^252-1 -> 0.088102024 | F5: =D5*252 -> 0.017985748
A6: National Grid plc | B6: NG.L | C6: =AVERAGE('Asset Returns'!J4:J2528) -> 9.9384476e-05 | D6: =AVERAGE('Asset Returns'!K4:K2528) -> 9.5938344e-06 | E6: =(1+C6)^252-1 -> 0.02535987 | F6: =D6*252 -> 0.0024176463
A7: Unilever PLC | B7: ULVR.L | C7: =AVERAGE('Asset Returns'!L4:L2528) -> 0.00014302618 | D7: =AVERAGE('Asset Returns'!M4:M2528) -> 6.2741882e-05 | E7: =(1+C7)^252-1 -> 0.036697335 | F7: =D7*252 -> 0.015810954
A8: Vanguard U.K. Gilt UCITS ETF | B8: VGOV.L | C8: =AVERAGE('Asset Returns'!N4:N2528) -> -6.8500988e-05 | D8: =AVERAGE('Asset Returns'!O4:O2528) -> -8.8510566e-05 | E8: =(1+C8)^252-1 -> -0.017114691 | F8: =D8*252 -> -0.022304663
A9: iShares Physical Gold ETC | B9: SGLN.L | C9: =AVERAGE('Asset Returns'!P4:P2528) -> 0.00049495874 | D9: =AVERAGE('Asset Returns'!Q4:Q2528) -> 0.00044794238 | E9: =(1+C9)^252-1 -> 0.13280714 | F9: =D9*252 -> 0.11288148

Sheet Covariance and Correlation
A1: Daily covariance matrix
B2: AAL.L | C2: BARC.L | D2: HSX.L | E2: MKS.L | F2: NG.L | G2: ULVR.L | H2: VGOV.L | I2: SGLN.L
A3: AAL.L | B3: =_xlfn.COVARIANCE.P('Asset Returns'!$C$4:$C$2528, 'Asset Returns'!C$4:C$2528) -> 0.00063053101 | C3: =_xlfn.COVARIANCE.P('Asset Returns'!$C$4:$C$2528, 'Asset Returns'!E$4:E$2528) -> 0.00021420866 | D3: =_xlfn.COVARIANCE.P('Asset Returns'!$C$4:$C$2528, 'Asset Returns'!G$4:G$2528) -> 8.5321854e-05 | E3: =_xlfn.COVARIANCE.P('Asset Returns'!$C$4:$C$2528, 'Asset Returns'!I$4:I$2528) -> 0.00011861789 | F3: =_xlfn.COVARIANCE.P('Asset Returns'!$C$4:$C$2528, 'Asset Returns'!K$4:K$2528) -> 4.222317e-05 | G3: =_xlfn.COVARIANCE.P('Asset Returns'!$C$4:$C$2528, 'Asset Returns'!M$4:M$2528) -> 1.737893e-05 | H3: =_xlfn.COVARIANCE.P('Asset Returns'!$C$4:$C$2528, 'Asset Returns'!O$4:O$2528) -> -1.0307817e-05 | I3: =_xlfn.COVARIANCE.P('Asset Returns'!$C$4:$C$2528, 'Asset Returns'!Q$4:Q$2528) -> 2.9204385e-05
A4: BARC.L | B4: =_xlfn.COVARIANCE.P('Asset Returns'!$E$4:$E$2528, 'Asset Returns'!C$4:C$2528) -> 0.00021420866 | C4: =_xlfn.COVARIANCE.P('Asset Returns'!$E$4:$E$2528, 'Asset Returns'!E$4:E$2528) -> 0.00044031507 | D4: =_xlfn.COVARIANCE.P('Asset Returns'!$E$4:$E$2528, 'Asset Returns'!G$4:G$2528) -> 0.00011317731 | E4: =_xlfn.COVARIANCE.P('Asset Returns'!$E$4:$E$2528, 'Asset Returns'!I$4:I$2528) -> 0.00017225757 | F4: =_xlfn.COVARIANCE.P('Asset Returns'!$E$4:$E$2528, 'Asset Returns'!K$4:K$2528) -> 3.4953955e-05 | G4: =_xlfn.COVARIANCE.P('Asset Returns'!$E$4:$E$2528, 'Asset Returns'!M$4:M$2528) -> 1.7969588e-05 | H4: =_xlfn.COVARIANCE.P('Asset Returns'!$E$4:$E$2528, 'Asset Returns'!O$4:O$2528) -> -1.7857133e-05 | I4: =_xlfn.COVARIANCE.P('Asset Returns'!$E$4:$E$2528, 'Asset Returns'!Q$4:Q$2528) -> -3.8253548e-05
A5: HSX.L | B5: =_xlfn.COVARIANCE.P('Asset Returns'!$G$4:$G$2528, 'Asset Returns'!C$4:C$2528) -> 8.5321854e-05 | C5: =_xlfn.COVARIANCE.P('Asset Returns'!$G$4:$G$2528, 'Asset Returns'!E$4:E$2528) -> 0.00011317731 | D5: =_xlfn.COVARIANCE.P('Asset Returns'!$G$4:$G$2528, 'Asset Returns'!G$4:G$2528) -> 0.00034213088 | E5: =_xlfn.COVARIANCE.P('Asset Returns'!$G$4:$G$2528, 'Asset Returns'!I$4:I$2528) -> 6.0273654e-05 | F5: =_xlfn.COVARIANCE.P('Asset Returns'!$G$4:$G$2528, 'Asset Returns'!K$4:K$2528) -> 3.380402e-05 | G5: =_xlfn.COVARIANCE.P('Asset Returns'!$G$4:$G$2528, 'Asset Returns'!M$4:M$2528) -> 3.6421275e-05 | H5: =_xlfn.COVARIANCE.P('Asset Returns'!$G$4:$G$2528, 'Asset Returns'!O$4:O$2528) -> 4.8359958e-06 | I5: =_xlfn.COVARIANCE.P('Asset Returns'!$G$4:$G$2528, 'Asset Returns'!Q$4:Q$2528) -> -1.1639579e-05
A6: MKS.L | B6: =_xlfn.COVARIANCE.P('Asset Returns'!$I$4:$I$2528, 'Asset Returns'!C$4:C$2528) -> 0.00011861789 | C6: =_xlfn.COVARIANCE.P('Asset Returns'!$I$4:$I$2528, 'Asset Returns'!E$4:E$2528) -> 0.00017225757 | D6: =_xlfn.COVARIANCE.P('Asset Returns'!$I$4:$I$2528, 'Asset Returns'!G$4:G$2528) -> 6.0273654e-05 | E6: =_xlfn.COVARIANCE.P('Asset Returns'!$I$4:$I$2528, 'Asset Returns'!I$4:I$2528) -> 0.00052648793 | F6: =_xlfn.COVARIANCE.P('Asset Returns'!$I$4:$I$2528, 'Asset Returns'!K$4:K$2528) -> 6.0665907e-05 | G6: =_xlfn.COVARIANCE.P('Asset Returns'!$I$4:$I$2528, 'Asset Returns'!M$4:M$2528) -> 3.4209161e-05 | H6: =_xlfn.COVARIANCE.P('Asset Returns'!$I$4:$I$2528, 'Asset Returns'!O$4:O$2528) -> -1.031485e-05 | I6: =_xlfn.COVARIANCE.P('Asset Returns'!$I$4:$I$2528, 'Asset Returns'!Q$4:Q$2528) -> -2.1943347e-05
A7: NG.L | B7: =_xlfn.COVARIANCE.P('Asset Returns'!$K$4:$K$2528, 'Asset Returns'!C$4:C$2528) -> 4.222317e-05 | C7: =_xlfn.COVARIANCE.P('Asset Returns'!$K$4:$K$2528, 'Asset Returns'!E$4:E$2528) -> 3.4953955e-05 | D7: =_xlfn.COVARIANCE.P('Asset Returns'!$K$4:$K$2528, 'Asset Returns'!G$4:G$2528) -> 3.380402e-05 | E7: =_xlfn.COVARIANCE.P('Asset Returns'!$K$4:$K$2528, 'Asset Returns'!I$4:I$2528) -> 6.0665907e-05 | F7: =_xlfn.COVARIANCE.P('Asset Returns'!$K$4:$K$2528, 'Asset Returns'!K$4:K$2528) -> 0.00018041293 | G7: =_xlfn.COVARIANCE.P('Asset Returns'!$K$4:$K$2528, 'Asset Returns'!M$4:M$2528) -> 6.0753158e-05 | H7: =_xlfn.COVARIANCE.P('Asset Returns'!$K$4:$K$2528, 'Asset Returns'!O$4:O$2528) -> 1.4520426e-05 | I7: =_xlfn.COVARIANCE.P('Asset Returns'!$K$4:$K$2528, 'Asset Returns'!Q$4:Q$2528) -> 1.3873579e-05
A8: ULVR.L | B8: =_xlfn.COVARIANCE.P('Asset Returns'!$M$4:$M$2528, 'Asset Returns'!C$4:C$2528) -> 1.737893e-05 | C8: =_xlfn.COVARIANCE.P('Asset Returns'!$M$4:$M$2528, 'Asset Returns'!E$4:E$2528) -> 1.7969588e-05 | D8: =_xlfn.COVARIANCE.P('Asset Returns'!$M$4:$M$2528, 'Asset Returns'!G$4:G$2528) -> 3.6421275e-05 | E8: =_xlfn.COVARIANCE.P('Asset Returns'!$M$4:$M$2528, 'Asset Returns'!I$4:I$2528) -> 3.4209161e-05 | F8: =_xlfn.COVARIANCE.P('Asset Returns'!$M$4:$M$2528, 'Asset Returns'!K$4:K$2528) -> 6.0753158e-05 | G8: =_xlfn.COVARIANCE.P('Asset Returns'!$M$4:$M$2528, 'Asset Returns'!M$4:M$2528) -> 0.00016021811 | H8: =_xlfn.COVARIANCE.P('Asset Returns'!$M$4:$M$2528, 'Asset Returns'!O$4:O$2528) -> 2.513128e-06 | I8: =_xlfn.COVARIANCE.P('Asset Returns'!$M$4:$M$2528, 'Asset Returns'!Q$4:Q$2528) -> 1.1460705e-05
A9: VGOV.L | B9: =_xlfn.COVARIANCE.P('Asset Returns'!$O$4:$O$2528, 'Asset Returns'!C$4:C$2528) -> -1.0307817e-05 | C9: =_xlfn.COVARIANCE.P('Asset Returns'!$O$4:$O$2528, 'Asset Returns'!E$4:E$2528) -> -1.7857133e-05 | D9: =_xlfn.COVARIANCE.P('Asset Returns'!$O$4:$O$2528, 'Asset Returns'!G$4:G$2528) -> 4.8359958e-06 | E9: =_xlfn.COVARIANCE.P('Asset Returns'!$O$4:$O$2528, 'Asset Returns'!I$4:I$2528) -> -1.031485e-05 | F9: =_xlfn.COVARIANCE.P('Asset Returns'!$O$4:$O$2528, 'Asset Returns'!K$4:K$2528) -> 1.4520426e-05 | G9: =_xlfn.COVARIANCE.P('Asset Returns'!$O$4:$O$2528, 'Asset Returns'!M$4:M$2528) -> 2.513128e-06 | H9: =_xlfn.COVARIANCE.P('Asset Returns'!$O$4:$O$2528, 'Asset Returns'!O$4:O$2528) -> 3.9950585e-05 | I9: =_xlfn.COVARIANCE.P('Asset Returns'!$O$4:$O$2528, 'Asset Returns'!Q$4:Q$2528) -> 1.1898299e-05
A10: SGLN.L | B10: =_xlfn.COVARIANCE.P('Asset Returns'!$Q$4:$Q$2528, 'Asset Returns'!C$4:C$2528) -> 2.9204385e-05 | C10: =_xlfn.COVARIANCE.P('Asset Returns'!$Q$4:$Q$2528, 'Asset Returns'!E$4:E$2528) -> -3.8253548e-05 | D10: =_xlfn.COVARIANCE.P('Asset Returns'!$Q$4:$Q$2528, 'Asset Returns'!G$4:G$2528) -> -1.1639579e-05 | E10: =_xlfn.COVARIANCE.P('Asset Returns'!$Q$4:$Q$2528, 'Asset Returns'!I$4:I$2528) -> -2.1943347e-05 | F10: =_xlfn.COVARIANCE.P('Asset Returns'!$Q$4:$Q$2528, 'Asset Returns'!K$4:K$2528) -> 1.3873579e-05 | G10: =_xlfn.COVARIANCE.P('Asset Returns'!$Q$4:$Q$2528, 'Asset Returns'!M$4:M$2528) -> 1.1460705e-05 | H10: =_xlfn.COVARIANCE.P('Asset Returns'!$Q$4:$Q$2528, 'Asset Returns'!O$4:O$2528) -> 1.1898299e-05 | I10: =_xlfn.COVARIANCE.P('Asset Returns'!$Q$4:$Q$2528, 'Asset Returns'!Q$4:Q$2528) -> 9.3882441e-05
A12: Annual covariance matrix
B13: AAL.L | C13: BARC.L | D13: HSX.L | E13: MKS.L | F13: NG.L | G13: ULVR.L | H13: VGOV.L | I13: SGLN.L
A14: AAL.L | B14: =_xlfn.COVARIANCE.P('Asset Returns'!$C$4:$C$2528, 'Asset Returns'!C$4:C$2528)*252 -> 0.15889382 | C14: =_xlfn.COVARIANCE.P('Asset Returns'!$C$4:$C$2528, 'Asset Returns'!E$4:E$2528)*252 -> 0.053980582 | D14: =_xlfn.COVARIANCE.P('Asset Returns'!$C$4:$C$2528, 'Asset Returns'!G$4:G$2528)*252 -> 0.021501107 | E14: =_xlfn.COVARIANCE.P('Asset Returns'!$C$4:$C$2528, 'Asset Returns'!I$4:I$2528)*252 -> 0.029891708 | F14: =_xlfn.COVARIANCE.P('Asset Returns'!$C$4:$C$2528, 'Asset Returns'!K$4:K$2528)*252 -> 0.010640239 | G14: =_xlfn.COVARIANCE.P('Asset Returns'!$C$4:$C$2528, 'Asset Returns'!M$4:M$2528)*252 -> 0.0043794902 | H14: =_xlfn.COVARIANCE.P('Asset Returns'!$C$4:$C$2528, 'Asset Returns'!O$4:O$2528)*252 -> -0.0025975698 | I14: =_xlfn.COVARIANCE.P('Asset Returns'!$C$4:$C$2528, 'Asset Returns'!Q$4:Q$2528)*252 -> 0.007359505
A15: BARC.L | B15: =_xlfn.COVARIANCE.P('Asset Returns'!$E$4:$E$2528, 'Asset Returns'!C$4:C$2528)*252 -> 0.053980582 | C15: =_xlfn.COVARIANCE.P('Asset Returns'!$E$4:$E$2528, 'Asset Returns'!E$4:E$2528)*252 -> 0.1109594 | D15: =_xlfn.COVARIANCE.P('Asset Returns'!$E$4:$E$2528, 'Asset Returns'!G$4:G$2528)*252 -> 0.028520681 | E15: =_xlfn.COVARIANCE.P('Asset Returns'!$E$4:$E$2528, 'Asset Returns'!I$4:I$2528)*252 -> 0.043408908 | F15: =_xlfn.COVARIANCE.P('Asset Returns'!$E$4:$E$2528, 'Asset Returns'!K$4:K$2528)*252 -> 0.0088083968 | G15: =_xlfn.COVARIANCE.P('Asset Returns'!$E$4:$E$2528, 'Asset Returns'!M$4:M$2528)*252 -> 0.0045283362 | H15: =_xlfn.COVARIANCE.P('Asset Returns'!$E$4:$E$2528, 'Asset Returns'!O$4:O$2528)*252 -> -0.0044999976 | I15: =_xlfn.COVARIANCE.P('Asset Returns'!$E$4:$E$2528, 'Asset Returns'!Q$4:Q$2528)*252 -> -0.009639894
A16: HSX.L | B16: =_xlfn.COVARIANCE.P('Asset Returns'!$G$4:$G$2528, 'Asset Returns'!C$4:C$2528)*252 -> 0.021501107 | C16: =_xlfn.COVARIANCE.P('Asset Returns'!$G$4:$G$2528, 'Asset Returns'!E$4:E$2528)*252 -> 0.028520681 | D16: =_xlfn.COVARIANCE.P('Asset Returns'!$G$4:$G$2528, 'Asset Returns'!G$4:G$2528)*252 -> 0.086216981 | E16: =_xlfn.COVARIANCE.P('Asset Returns'!$G$4:$G$2528, 'Asset Returns'!I$4:I$2528)*252 -> 0.015188961 | F16: =_xlfn.COVARIANCE.P('Asset Returns'!$G$4:$G$2528, 'Asset Returns'!K$4:K$2528)*252 -> 0.008518613 | G16: =_xlfn.COVARIANCE.P('Asset Returns'!$G$4:$G$2528, 'Asset Returns'!M$4:M$2528)*252 -> 0.0091781614 | H16: =_xlfn.COVARIANCE.P('Asset Returns'!$G$4:$G$2528, 'Asset Returns'!O$4:O$2528)*252 -> 0.0012186709 | I16: =_xlfn.COVARIANCE.P('Asset Returns'!$G$4:$G$2528, 'Asset Returns'!Q$4:Q$2528)*252 -> -0.002933174
A17: MKS.L | B17: =_xlfn.COVARIANCE.P('Asset Returns'!$I$4:$I$2528, 'Asset Returns'!C$4:C$2528)*252 -> 0.029891708 | C17: =_xlfn.COVARIANCE.P('Asset Returns'!$I$4:$I$2528, 'Asset Returns'!E$4:E$2528)*252 -> 0.043408908 | D17: =_xlfn.COVARIANCE.P('Asset Returns'!$I$4:$I$2528, 'Asset Returns'!G$4:G$2528)*252 -> 0.015188961 | E17: =_xlfn.COVARIANCE.P('Asset Returns'!$I$4:$I$2528, 'Asset Returns'!I$4:I$2528)*252 -> 0.13267496 | F17: =_xlfn.COVARIANCE.P('Asset Returns'!$I$4:$I$2528, 'Asset Returns'!K$4:K$2528)*252 -> 0.015287809 | G17: =_xlfn.COVARIANCE.P('Asset Returns'!$I$4:$I$2528, 'Asset Returns'!M$4:M$2528)*252 -> 0.0086207085 | H17: =_xlfn.COVARIANCE.P('Asset Returns'!$I$4:$I$2528, 'Asset Returns'!O$4:O$2528)*252 -> -0.0025993421 | I17: =_xlfn.COVARIANCE.P('Asset Returns'!$I$4:$I$2528, 'Asset Returns'!Q$4:Q$2528)*252 -> -0.0055297233
A18: NG.L | B18: =_xlfn.COVARIANCE.P('Asset Returns'!$K$4:$K$2528, 'Asset Returns'!C$4:C$2528)*252 -> 0.010640239 | C18: =_xlfn.COVARIANCE.P('Asset Returns'!$K$4:$K$2528, 'Asset Returns'!E$4:E$2528)*252 -> 0.0088083968 | D18: =_xlfn.COVARIANCE.P('Asset Returns'!$K$4:$K$2528, 'Asset Returns'!G$4:G$2528)*252 -> 0.008518613 | E18: =_xlfn.COVARIANCE.P('Asset Returns'!$K$4:$K$2528, 'Asset Returns'!I$4:I$2528)*252 -> 0.015287809 | F18: =_xlfn.COVARIANCE.P('Asset Returns'!$K$4:$K$2528, 'Asset Returns'!K$4:K$2528)*252 -> 0.045464059 | G18: =_xlfn.COVARIANCE.P('Asset Returns'!$K$4:$K$2528, 'Asset Returns'!M$4:M$2528)*252 -> 0.015309796 | H18: =_xlfn.COVARIANCE.P('Asset Returns'!$K$4:$K$2528, 'Asset Returns'!O$4:O$2528)*252 -> 0.0036591473 | I18: =_xlfn.COVARIANCE.P('Asset Returns'!$K$4:$K$2528, 'Asset Returns'!Q$4:Q$2528)*252 -> 0.0034961419
A19: ULVR.L | B19: =_xlfn.COVARIANCE.P('Asset Returns'!$M$4:$M$2528, 'Asset Returns'!C$4:C$2528)*252 -> 0.0043794902 | C19: =_xlfn.COVARIANCE.P('Asset Returns'!$M$4:$M$2528, 'Asset Returns'!E$4:E$2528)*252 -> 0.0045283362 | D19: =_xlfn.COVARIANCE.P('Asset Returns'!$M$4:$M$2528, 'Asset Returns'!G$4:G$2528)*252 -> 0.0091781614 | E19: =_xlfn.COVARIANCE.P('Asset Returns'!$M$4:$M$2528, 'Asset Returns'!I$4:I$2528)*252 -> 0.0086207085 | F19: =_xlfn.COVARIANCE.P('Asset Returns'!$M$4:$M$2528, 'Asset Returns'!K$4:K$2528)*252 -> 0.015309796 | G19: =_xlfn.COVARIANCE.P('Asset Returns'!$M$4:$M$2528, 'Asset Returns'!M$4:M$2528)*252 -> 0.040374963 | H19: =_xlfn.COVARIANCE.P('Asset Returns'!$M$4:$M$2528, 'Asset Returns'!O$4:O$2528)*252 -> 0.00063330825 | I19: =_xlfn.COVARIANCE.P('Asset Returns'!$M$4:$M$2528, 'Asset Returns'!Q$4:Q$2528)*252 -> 0.0028880977
A20: VGOV.L | B20: =_xlfn.COVARIANCE.P('Asset Returns'!$O$4:$O$2528, 'Asset Returns'!C$4:C$2528)*252 -> -0.0025975698 | C20: =_xlfn.COVARIANCE.P('Asset Returns'!$O$4:$O$2528, 'Asset Returns'!E$4:E$2528)*252 -> -0.0044999976 | D20: =_xlfn.COVARIANCE.P('Asset Returns'!$O$4:$O$2528, 'Asset Returns'!G$4:G$2528)*252 -> 0.0012186709 | E20: =_xlfn.COVARIANCE.P('Asset Returns'!$O$4:$O$2528, 'Asset Returns'!I$4:I$2528)*252 -> -0.0025993421 | F20: =_xlfn.COVARIANCE.P('Asset Returns'!$O$4:$O$2528, 'Asset Returns'!K$4:K$2528)*252 -> 0.0036591473 | G20: =_xlfn.COVARIANCE.P('Asset Returns'!$O$4:$O$2528, 'Asset Returns'!M$4:M$2528)*252 -> 0.00063330825 | H20: =_xlfn.COVARIANCE.P('Asset Returns'!$O$4:$O$2528, 'Asset Returns'!O$4:O$2528)*252 -> 0.010067547 | I20: =_xlfn.COVARIANCE.P('Asset Returns'!$O$4:$O$2528, 'Asset Returns'!Q$4:Q$2528)*252 -> 0.0029983714
A21: SGLN.L | B21: =_xlfn.COVARIANCE.P('Asset Returns'!$Q$4:$Q$2528, 'Asset Returns'!C$4:C$2528)*252 -> 0.007359505 | C21: =_xlfn.COVARIANCE.P('Asset Returns'!$Q$4:$Q$2528, 'Asset Returns'!E$4:E$2528)*252 -> -0.009639894 | D21: =_xlfn.COVARIANCE.P('Asset Returns'!$Q$4:$Q$2528, 'Asset Returns'!G$4:G$2528)*252 -> -0.002933174 | E21: =_xlfn.COVARIANCE.P('Asset Returns'!$Q$4:$Q$2528, 'Asset Returns'!I$4:I$2528)*252 -> -0.0055297233 | F21: =_xlfn.COVARIANCE.P('Asset Returns'!$Q$4:$Q$2528, 'Asset Returns'!K$4:K$2528)*252 -> 0.0034961419 | G21: =_xlfn.COVARIANCE.P('Asset Returns'!$Q$4:$Q$2528, 'Asset Returns'!M$4:M$2528)*252 -> 0.0028880977 | H21: =_xlfn.COVARIANCE.P('Asset Returns'!$Q$4:$Q$2528, 'Asset Returns'!O$4:O$2528)*252 -> 0.0029983714 | I21: =_xlfn.COVARIANCE.P('Asset Returns'!$Q$4:$Q$2528, 'Asset Returns'!Q$4:Q$2528)*252 -> 0.023658375
B23: AAL.L | C23: BARC.L | D23: HSX.L | E23: MKS.L | F23: NG.L | G23: ULVR.L | H23: VGOV.L | I23: SGLN.L
A24: Daily return variance | B24: =_xlfn.VAR.P('Asset Returns'!C4:C2528) -> 0.00063053101 | C24: =_xlfn.VAR.P('Asset Returns'!E4:E2528) -> 0.00044031507 | D24: =_xlfn.VAR.P('Asset Returns'!G4:G2528) -> 0.00034213088 | E24: =_xlfn.VAR.P('Asset Returns'!I4:I2528) -> 0.00052648793 | F24: =_xlfn.VAR.P('Asset Returns'!K4:K2528) -> 0.00018041293 | G24: =_xlfn.VAR.P('Asset Returns'!M4:M2528) -> 0.00016021811 | H24: =_xlfn.VAR.P('Asset Returns'!O4:O2528) -> 3.9950585e-05 | I24: =_xlfn.VAR.P('Asset Returns'!Q4:Q2528) -> 9.3882441e-05
A26: Correlation Matrix
B27: AAL.L | C27: BARC.L | D27: HSX.L | E27: MKS.L | F27: NG.L | G27: ULVR.L | H27: VGOV.L | I27: SGLN.L
A28: AAL.L | B28: =CORREL('Asset Returns'!$C$4:$C$2528, 'Asset Returns'!C$4:C$2528) -> 1 | C28: =CORREL('Asset Returns'!$C$4:$C$2528, 'Asset Returns'!E$4:E$2528) -> 0.40650661 | D28: =CORREL('Asset Returns'!$C$4:$C$2528, 'Asset Returns'!G$4:G$2528) -> 0.18370075 | E28: =CORREL('Asset Returns'!$C$4:$C$2528, 'Asset Returns'!I$4:I$2528) -> 0.20587459 | F28: =CORREL('Asset Returns'!$C$4:$C$2528, 'Asset Returns'!K$4:K$2528) -> 0.12518831 | G28: =CORREL('Asset Returns'!$C$4:$C$2528, 'Asset Returns'!M$4:M$2528) -> 0.054678173 | H28: =CORREL('Asset Returns'!$C$4:$C$2528, 'Asset Returns'!O$4:O$2528) -> -0.064940777 | I28: =CORREL('Asset Returns'!$C$4:$C$2528, 'Asset Returns'!Q$4:Q$2528) -> 0.12003355
A29: BARC.L | B29: =CORREL('Asset Returns'!$E$4:$E$2528, 'Asset Returns'!C$4:C$2528) -> 0.40650661 | C29: =CORREL('Asset Returns'!$E$4:$E$2528, 'Asset Returns'!E$4:E$2528) -> 1 | D29: =CORREL('Asset Returns'!$E$4:$E$2528, 'Asset Returns'!G$4:G$2528) -> 0.29154205 | E29: =CORREL('Asset Returns'!$E$4:$E$2528, 'Asset Returns'!I$4:I$2528) -> 0.35770126 | F29: =CORREL('Asset Returns'!$E$4:$E$2528, 'Asset Returns'!K$4:K$2528) -> 0.12399384 | G29: =CORREL('Asset Returns'!$E$4:$E$2528, 'Asset Returns'!M$4:M$2528) -> 0.067665837 | H29: =CORREL('Asset Returns'!$E$4:$E$2528, 'Asset Returns'!O$4:O$2528) -> -0.13463823 | I29: =CORREL('Asset Returns'!$E$4:$E$2528, 'Asset Returns'!Q$4:Q$2528) -> -0.1881277
A30: HSX.L | B30: =CORREL('Asset Returns'!$G$4:$G$2528, 'Asset Returns'!C$4:C$2528) -> 0.18370075 | C30: =CORREL('Asset Returns'!$G$4:$G$2528, 'Asset Returns'!E$4:E$2528) -> 0.29154205 | D30: =CORREL('Asset Returns'!$G$4:$G$2528, 'Asset Returns'!G$4:G$2528) -> 1 | E30: =CORREL('Asset Returns'!$G$4:$G$2528, 'Asset Returns'!I$4:I$2528) -> 0.14201597 | F30: =CORREL('Asset Returns'!$G$4:$G$2528, 'Asset Returns'!K$4:K$2528) -> 0.13606248 | G30: =CORREL('Asset Returns'!$G$4:$G$2528, 'Asset Returns'!M$4:M$2528) -> 0.15556189 | H30: =CORREL('Asset Returns'!$G$4:$G$2528, 'Asset Returns'!O$4:O$2528) -> 0.041356899 | I30: =CORREL('Asset Returns'!$G$4:$G$2528, 'Asset Returns'!Q$4:Q$2528) -> -0.064945484
A31: MKS.L | B31: =CORREL('Asset Returns'!$I$4:$I$2528, 'Asset Returns'!C$4:C$2528) -> 0.20587459 | C31: =CORREL('Asset Returns'!$I$4:$I$2528, 'Asset Returns'!E$4:E$2528) -> 0.35770126 | D31: =CORREL('Asset Returns'!$I$4:$I$2528, 'Asset Returns'!G$4:G$2528) -> 0.14201597 | E31: =CORREL('Asset Returns'!$I$4:$I$2528, 'Asset Returns'!I$4:I$2528) -> 1 | F31: =CORREL('Asset Returns'!$I$4:$I$2528, 'Asset Returns'!K$4:K$2528) -> 0.19684149 | G31: =CORREL('Asset Returns'!$I$4:$I$2528, 'Asset Returns'!M$4:M$2528) -> 0.11778566 | H31: =CORREL('Asset Returns'!$I$4:$I$2528, 'Asset Returns'!O$4:O$2528) -> -0.071109112 | I31: =CORREL('Asset Returns'!$I$4:$I$2528, 'Asset Returns'!Q$4:Q$2528) -> -0.098699844
A32: NG.L | B32: =CORREL('Asset Returns'!$K$4:$K$2528, 'Asset Returns'!C$4:C$2528) -> 0.12518831 | C32: =CORREL('Asset Returns'!$K$4:$K$2528, 'Asset Returns'!E$4:E$2528) -> 0.12399384 | D32: =CORREL('Asset Returns'!$K$4:$K$2528, 'Asset Returns'!G$4:G$2528) -> 0.13606248 | E32: =CORREL('Asset Returns'!$K$4:$K$2528, 'Asset Returns'!I$4:I$2528) -> 0.19684149 | F32: =CORREL('Asset Returns'!$K$4:$K$2528, 'Asset Returns'!K$4:K$2528) -> 1 | G32: =CORREL('Asset Returns'!$K$4:$K$2528, 'Asset Returns'!M$4:M$2528) -> 0.35733802 | H32: =CORREL('Asset Returns'!$K$4:$K$2528, 'Asset Returns'!O$4:O$2528) -> 0.17100285 | I32: =CORREL('Asset Returns'!$K$4:$K$2528, 'Asset Returns'!Q$4:Q$2528) -> 0.1066013
A33: ULVR.L | B33: =CORREL('Asset Returns'!$M$4:$M$2528, 'Asset Returns'!C$4:C$2528) -> 0.054678173 | C33: =CORREL('Asset Returns'!$M$4:$M$2528, 'Asset Returns'!E$4:E$2528) -> 0.067665837 | D33: =CORREL('Asset Returns'!$M$4:$M$2528, 'Asset Returns'!G$4:G$2528) -> 0.15556189 | E33: =CORREL('Asset Returns'!$M$4:$M$2528, 'Asset Returns'!I$4:I$2528) -> 0.11778566 | F33: =CORREL('Asset Returns'!$M$4:$M$2528, 'Asset Returns'!K$4:K$2528) -> 0.35733802 | G33: =CORREL('Asset Returns'!$M$4:$M$2528, 'Asset Returns'!M$4:M$2528) -> 1 | H33: =CORREL('Asset Returns'!$M$4:$M$2528, 'Asset Returns'!O$4:O$2528) -> 0.031417103 | I33: =CORREL('Asset Returns'!$M$4:$M$2528, 'Asset Returns'!Q$4:Q$2528) -> 0.093446569
A34: VGOV.L | B34: =CORREL('Asset Returns'!$O$4:$O$2528, 'Asset Returns'!C$4:C$2528) -> -0.064940777 | C34: =CORREL('Asset Returns'!$O$4:$O$2528, 'Asset Returns'!E$4:E$2528) -> -0.13463823 | D34: =CORREL('Asset Returns'!$O$4:$O$2528, 'Asset Returns'!G$4:G$2528) -> 0.041356899 | E34: =CORREL('Asset Returns'!$O$4:$O$2528, 'Asset Returns'!I$4:I$2528) -> -0.071109112 | F34: =CORREL('Asset Returns'!$O$4:$O$2528, 'Asset Returns'!K$4:K$2528) -> 0.17100285 | G34: =CORREL('Asset Returns'!$O$4:$O$2528, 'Asset Returns'!M$4:M$2528) -> 0.031417103 | H34: =CORREL('Asset Returns'!$O$4:$O$2528, 'Asset Returns'!O$4:O$2528) -> 1 | I34: =CORREL('Asset Returns'!$O$4:$O$2528, 'Asset Returns'!Q$4:Q$2528) -> 0.19426122
A35: SGLN.L | B35: =CORREL('Asset Returns'!$Q$4:$Q$2528, 'Asset Returns'!C$4:C$2528) -> 0.12003355 | C35: =CORREL('Asset Returns'!$Q$4:$Q$2528, 'Asset Returns'!E$4:E$2528) -> -0.1881277 | D35: =CORREL('Asset Returns'!$Q$4:$Q$2528, 'Asset Returns'!G$4:G$2528) -> -0.064945484 | E35: =CORREL('Asset Returns'!$Q$4:$Q$2528, 'Asset Returns'!I$4:I$2528) -> -0.098699844 | F35: =CORREL('Asset Returns'!$Q$4:$Q$2528, 'Asset Returns'!K$4:K$2528) -> 0.1066013 | G35: =CORREL('Asset Returns'!$Q$4:$Q$2528, 'Asset Returns'!M$4:M$2528) -> 0.093446569 | H35: =CORREL('Asset Returns'!$Q$4:$Q$2528, 'Asset Returns'!O$4:O$2528) -> 0.19426122 | I35: =CORREL('Asset Returns'!$Q$4:$Q$2528, 'Asset Returns'!Q$4:Q$2528) -> 1

Sheet Efficient Frontier
A2: Portfolio return | B2: =SUMPRODUCT(B8:B15,Table13[Average Annualised Log Return]) -> 0.11642783 | E2: Current 10-year Treasury yield | F2: 0.0469
A3: Portfolio variance | B3: {=MMULT(MMULT(TRANSPOSE(B8:B15), 'Covariance and Correlation'!B14:I21), B8:B15)} -> 0.028655526 | E3: Target portfolio return | F3: 0.11642777
A4: Portfolio volatility | B4: =SQRT(B3) -> 0.16927943
A5: Sharpe ratio | B5: =(B2-F2)/B4 -> 0.41072817
B7: Weights | D7: Sharpe Ratio | E7: Portfolio Volatility | F7: Portfolio Return
A8: AAL.L | B8: 0.22070515 | D8: =(F8-$F$2)/E8 -> -0.47062084 | E8: =SQRT(B53) -> 0.078407067 | F8: 0.01
A9: BARC.L | B9: 0.28223547 | D9: =(F9-$F$2)/E9 -> -0.34845562 | E9: =SQRT(B54) -> 0.077197779 | F9: 0.02
A10: HSX.L | B10: 0.075584334 | D10: =(F10-$F$2)/E10 -> -0.21796454 | E10: =SQRT(B55) -> 0.077535545 | F10: 0.030000001
A11: MKS.L | B11: 0 | D11: =(F11-$F$2)/E11 -> -0.086727128 | E11: =SQRT(B56) -> 0.079560797 | F11: 0.039999921
A12: NG.L | B12: 0 | D12: =(F12-$F$2)/E12 -> 0.037490674 | E12: =SQRT(B57) -> 0.082688031 | F12: 0.05000003
A13: ULVR.L | B13: 0.021475055 | D13: =(F13-$F$2)/E13 -> 0.15014172 | E13: =SQRT(B58) -> 0.087250892 | F13: 0.059999999
A14: VGOV.L | B14: 0 | D14: =(F14-$F$2)/E14 -> 0.24866039 | E14: =SQRT(B59) -> 0.092897787 | F14: 0.07
A15: SGLN.L | B15: 0.4 | D15: =(F15-$F$2)/E15 -> 0.33284996 | E15: =SQRT(B60) -> 0.099444206 | F15: 0.08
A16: Sum | B16: =SUM(B8:B15) -> 1 | D16: =(F16-$F$2)/E16 -> 0.40384305 | E16: =SQRT(B61) -> 0.1067248 | F16: 0.09000007
D17: =(F17-$F$2)/E17 -> 0.46335279 | E17: =SQRT(B62) -> 0.11459963 | F17: 0.10000006
A18: Maximum Sharpe ratio | B18: Portfolio return | D18: =(F18-$F$2)/E18 -> 0.5124595 | E18: =SQRT(B63) -> 0.12313168 | F18: 0.11
A19: 0.53047054 | B19: 0.11642777 | D19: =(F19-$F$2)/E19 -> 0.5168043 | E19: =SQRT(B64) -> 0.14144619 | F19: 0.12
A20: Portfolio variance | B20: Portfolio volatility | D20: =(F20-$F$2)/E20 -> 0.41956069 | E20: =SQRT(B65) -> 0.19806457 | F20: 0.13000011
A21: 0.017178847 | B21: =SQRT(A21) -> 0.1310681 | D21: =(F21-$F$2)/E21 -> 0.33802763 | E21: =SQRT(B66) -> 0.27542166 | F21: 0.14000013
D22: =(F22-$F$2)/E22 -> 0.28338444 | E22: =SQRT(B67) -> 0.36381722 | F22: 0.15000014
A23: Capital Allocation Line
A24: Volatility (CAL) | B24: Return (CAL)
A25: 0 | B25: =$F$2+$A$19*A25 -> 0.0469
A26: 0.05 | B26: =$F$2+$A$19*A26 -> 0.073423527
A27: 0.1 | B27: =$F$2+$A$19*A27 -> 0.099947054
A28: 0.15 | B28: =$F$2+$A$19*A28 -> 0.12647058
A29: 0.2 | B29: =$F$2+$A$19*A29 -> 0.15299411
A30: 0.25 | B30: =$F$2+$A$19*A30 -> 0.17951763
A31: 0.3 | B31: =$F$2+$A$19*A31 -> 0.20604116
A32: 0.35 | B32: =$F$2+$A$19*A32 -> 0.23256469
A33: 0.4 | B33: =$F$2+$A$19*A33 -> 0.25908821
A36: Ticker | B36: Average Volatility | C36: Average Returns
A37: AAL.L | B37: =_xlfn.STDEV.P('Asset Returns'!C4:C2528)*SQRT(252) -> 0.39861487 | C37: ='Average Returns'!E2 -> 0.26243322
A38: BARC.L | B38: =_xlfn.STDEV.P('Asset Returns'!E4:E2528)*SQRT(252) -> 0.33310569 | C38: ='Average Returns'!E3 -> 0.18810324
A39: HSX.L | B39: =_xlfn.STDEV.P('Asset Returns'!G4:G2528)*SQRT(252) -> 0.29362728 | C39: ='Average Returns'!E4 -> 0.10047423
A40: MKS.L | B40: =_xlfn.STDEV.P('Asset Returns'!I4:I2528)*SQRT(252) -> 0.36424574 | C40: ='Average Returns'!E5 -> 0.088102024
A41: NG.L | B41: =_xlfn.STDEV.P('Asset Returns'!K4:K2528)*SQRT(252) -> 0.21322303 | C41: ='Average Returns'!E6 -> 0.02535987
A42: ULVR.L | B42: =_xlfn.STDEV.P('Asset Returns'!M4:M2528)*SQRT(252) -> 0.20093522 | C42: ='Average Returns'!E7 -> 0.036697335
A43: VGOV.L | B43: =_xlfn.STDEV.P('Asset Returns'!O4:O2528)*SQRT(252) -> 0.10033717 | C43: ='Average Returns'!E8 -> -0.017114691
A44: SGLN.L | B44: =_xlfn.STDEV.P('Asset Returns'!Q4:Q2528)*SQRT(252) -> 0.15381279 | C44: ='Average Returns'!E9 -> 0.13280714
...

Sheet AAL L
A1: Date | B1: Open | C1: High | D1: Low | E1: Close | F1: Adj Close | G1: Volume | H1: Dividends | I1: Stock Splits
A2: 2016-08-17 00:00:00+01:00 | B2: 867.34052 | C2: 876.62811 | D2: 838.34131 | E2: 845.2738 | F2: 841.43579 | G2: 6991036 | H2: 0 | I2: 0
A3: 2016-08-18 00:00:00+01:00 | B3: 854.35431 | C3: 870.66028 | D3: 852.98743 | E3: 859.23639 | F3: 855.33496 | G3: 4235858 | H3: 0 | I3: 0
A4: 2016-08-19 00:00:00+01:00 | B4: 861.77502 | C4: 866.26648 | D4: 839.70831 | E4: 849.47229 | F4: 845.6153 | G4: 4911050 | H4: 0 | I4: 0
A5: 2016-08-22 00:00:00+01:00 | B5: 843.8092 | C5: 843.8092 | D5: 806.21759 | E5: 815.2981 | F5: 811.59625 | G5: 6463432 | H5: 0 | I5: 0
A6: 2016-08-23 00:00:00+01:00 | B6: 823.5976 | C6: 857.38123 | D6: 823.30469 | E6: 855.42841 | F6: 851.54425 | G6: 5795783 | H6: 0 | I6: 0
A7: 2016-08-24 00:00:00+01:00 | B7: 849.86292 | C7: 849.96051 | D7: 820.9613 | E7: 828.57721 | F7: 824.815 | G7: 7651614 | H7: 0 | I7: 0
A8: 2016-08-25 00:00:00+01:00 | B8: 821.74237 | C8: 827.30792 | D8: 802.60492 | E8: 819.78961 | F8: 816.06726 | G8: 5970198 | H8: 0 | I8: 0
A9: 2016-08-26 00:00:00+01:00 | B9: 822.91412 | C9: 844.29742 | D9: 815.39581 | E9: 838.24359 | F9: 834.43732 | G9: 7233079 | H9: 0 | I9: 0
A10: 2016-08-30 00:00:00+01:00 | B10: 834.63098 | C10: 834.72858 | D10: 794.98889 | E10: 798.211 | F10: 794.58661 | G10: 6762783 | H10: 0 | I10: 0
A11: 2016-08-31 00:00:00+01:00 | B11: 792.74323 | C11: 792.74323 | D11: 755.44452 | E11: 761.40057 | F11: 757.9433 | G11: 9649318 | H11: 0 | I11: 0
A12: 2016-09-01 00:00:00+01:00 | B12: 770.38348 | C12: 818.94989 | D12: 747.04742 | E12: 770.09058 | F12: 766.59387 | G12: 8711111 | H12: 0 | I12: 0
A13: 2016-09-02 00:00:00+01:00 | B13: 774.48438 | C13: 805.82703 | D13: 758.86188 | E13: 788.93518 | F13: 785.35297 | G13: 11374891 | H13: 0 | I13: 0
... A2527: 2026-08-17 00:00:00+01:00 | B2527: 3934 | C2527: 3957 | D2527: 3890 | E2527: 3928 | F2527: 3928 | G2527: 11338127 | H2527: 0 | I2527: 0

Sheet BARC L
A1: Date | B1: Open | C1: High | D1: Low | E1: Close | F1: Adj Close | G1: Volume | H1: Dividends | I1: Stock Splits
A2: 2016-08-17 00:00:00+01:00 | B2: 163 | C2: 163.75 | D2: 158.89999 | E2: 160.14999 | F2: 159.71347 | G2: 71229139 | H2: 0 | I2: 0
A3: 2016-08-18 00:00:00+01:00 | B3: 160.64999 | C3: 161.89999 | D3: 159.35001 | E3: 160.64999 | F3: 160.21208 | G3: 36619265 | H3: 0 | I3: 0
A4: 2016-08-19 00:00:00+01:00 | B4: 160.64999 | C4: 161.25 | D4: 158.481 | E4: 160.35001 | F4: 159.91293 | G4: 30692286 | H4: 0 | I4: 0
A5: 2016-08-22 00:00:00+01:00 | B5: 161.05 | C5: 163.244 | D5: 159.2 | E5: 160.05 | F5: 159.61377 | G5: 25327765 | H5: 0 | I5: 0
A6: 2016-08-23 00:00:00+01:00 | B6: 161.35001 | C6: 165.60001 | D6: 160.95 | E6: 164.60001 | F6: 164.15132 | G6: 37672688 | H6: 0 | I6: 0
A7: 2016-08-24 00:00:00+01:00 | B7: 163.10001 | C7: 168.05 | D7: 162.3 | E7: 166.55 | F7: 166.09601 | G7: 39674874 | H7: 0 | I7: 0
A8: 2016-08-25 00:00:00+01:00 | B8: 165.75 | C8: 166.8 | D8: 163.75 | E8: 164.35001 | F8: 163.90205 | G8: 28150000 | H8: 0 | I8: 0
A9: 2016-08-26 00:00:00+01:00 | B9: 163.60001 | C9: 166.55 | D9: 163.14999 | E9: 166 | F9: 165.54752 | G9: 27054906 | H9: 0 | I9: 0
A10: 2016-08-30 00:00:00+01:00 | B10: 165 | C10: 169.7 | D10: 165 | E10: 169.14999 | F10: 168.68896 | G10: 53494393 | H10: 0 | I10: 0
A11: 2016-08-31 00:00:00+01:00 | B11: 169.45 | C11: 175 | D11: 169.2 | E11: 172.25 | F11: 171.78049 | G11: 60135714 | H11: 0 | I11: 0
A12: 2016-09-01 00:00:00+01:00 | B12: 173.25 | C12: 177.39999 | D12: 169.75 | E12: 171.55 | F12: 171.0824 | G12: 52656119 | H12: 0 | I12: 0
A13: 2016-09-02 00:00:00+01:00 | B13: 173.10001 | C13: 175.5 | D13: 169.019 | E13: 174.3 | F13: 173.82494 | G13: 62995077 | H13: 0 | I13: 0
... A2526: 2026-08-17 00:00:00+01:00 | B2526: 523.5 | C2526: 523.59998 | D2526: 514.40002 | E2526: 515.40002 | F2526: 515.40002 | G2526: 37398641 | H2526: 0 | I2526: 0

Sheet HSX L
A1: Date | B1: Open | C1: High | D1: Low | E1: Close | F1: Adj Close | G1: Volume | H1: Dividends | I1: Stock Splits
A2: 2016-08-17 00:00:00+01:00 | B2: 1075 | C2: 1076 | D2: 1066 | E2: 1066 | F2: 1063.8091 | G2: 208568 | H2: 0 | I2: 0
A3: 2016-08-18 00:00:00+01:00 | B3: 1071 | C3: 1076.6 | D3: 1059 | E3: 1066 | F3: 1063.8091 | G3: 258610 | H3: 0 | I3: 0
A4: 2016-08-19 00:00:00+01:00 | B4: 1068 | C4: 1068 | D4: 1048 | E4: 1054 | F4: 1051.834 | G4: 290241 | H4: 0 | I4: 0
A5: 2016-08-22 00:00:00+01:00 | B5: 1051 | C5: 1063.6541 | D5: 1050 | E5: 1058 | F5: 1055.8257 | G5: 180849 | H5: 0 | I5: 0
A6: 2016-08-23 00:00:00+01:00 | B6: 1057 | C6: 1064 | D6: 1051 | E6: 1059 | F6: 1056.8237 | G6: 286020 | H6: 0 | I6: 0
A7: 2016-08-24 00:00:00+01:00 | B7: 1053 | C7: 1067 | D7: 1051.45 | E7: 1059 | F7: 1056.8237 | G7: 227314 | H7: 0 | I7: 0
A8: 2016-08-25 00:00:00+01:00 | B8: 1059 | C8: 1059 | D8: 1047 | E8: 1054 | F8: 1051.834 | G8: 259069 | H8: 0 | I8: 0
A9: 2016-08-26 00:00:00+01:00 | B9: 1049 | C9: 1055 | D9: 1046 | E9: 1052 | F9: 1049.8381 | G9: 255426 | H9: 0 | I9: 0
A10: 2016-08-30 00:00:00+01:00 | B10: 1046 | C10: 1061 | D10: 1046 | E10: 1054 | F10: 1051.834 | G10: 318564 | H10: 0 | I10: 0
A11: 2016-08-31 00:00:00+01:00 | B11: 1049 | C11: 1062 | D11: 1041 | E11: 1044 | F11: 1041.8546 | G11: 378396 | H11: 0 | I11: 0
A12: 2016-09-01 00:00:00+01:00 | B12: 1043 | C12: 1058 | D12: 1043 | E12: 1049 | F12: 1046.8441 | G12: 327330 | H12: 0 | I12: 0
A13: 2016-09-02 00:00:00+01:00 | B13: 1056 | C13: 1083 | D13: 1049 | E13: 1080 | F13: 1077.7805 | G13: 441102 | H13: 0 | I13: 0
... A2527: 2026-08-17 00:00:00+01:00 | B2527: 1790 | C2527: 1817 | D2527: 1785 | E2527: 1804 | F2527: 1804 | G2527: 768706 | H2527: 0 | I2527: 0

Sheet MKS L
A1: Date | B1: Open | C1: High | D1: Low | E1: Close | F1: Adj Close | G1: Volume | H1: Dividends | I1: Stock Splits
A2: 2016-08-17 00:00:00+01:00 | B2: 320.22549 | C2: 321.36481 | D2: 317.47229 | E2: 319.37109 | F2: 318.67081 | G2: 4446893 | H2: 0 | I2: 0
A3: 2016-08-18 00:00:00+01:00 | B3: 320.22549 | C3: 325.52881 | D3: 320.03561 | E3: 322.0293 | F3: 321.32312 | G3: 6940378 | H3: 0 | I3: 0
A4: 2016-08-19 00:00:00+01:00 | B4: 322.88379 | C4: 322.9787 | D4: 318.6116 | E4: 320.51031 | F4: 319.80743 | G4: 3589169 | H4: 0 | I4: 0
A5: 2016-08-22 00:00:00+01:00 | B5: 320.41541 | C5: 323.16861 | D5: 319.27609 | E5: 319.84579 | F5: 319.14444 | G5: 4128633 | H5: 0 | I5: 0
A6: 2016-08-23 00:00:00+01:00 | B6: 322.78879 | C6: 322.78879 | D6: 319.65591 | E6: 319.9407 | F6: 319.23914 | G6: 7918361 | H6: 0 | I6: 0
A7: 2016-08-24 00:00:00+01:00 | B7: 319.84579 | C7: 321.74451 | D7: 318.32681 | E7: 320.89011 | F7: 320.18643 | G7: 9984562 | H7: 0 | I7: 0
A8: 2016-08-25 00:00:00+01:00 | B8: 320.7951 | C8: 330.0383 | D8: 319.18121 | E8: 329.3396 | F8: 328.61746 | G8: 12474634 | H8: 0 | I8: 0
A9: 2016-08-26 00:00:00+01:00 | B9: 326.5864 | C9: 330.7532 | D9: 326.01669 | E9: 327.53571 | F9: 326.81754 | G9: 6363624 | H9: 0 | I9: 0
A10: 2016-08-30 00:00:00+01:00 | B10: 326.01669 | C10: 328.48511 | D10: 323.4534 | E10: 323.73819 | F10: 323.02832 | G10: 6382709 | H10: 0 | I10: 0
A11: 2016-08-31 00:00:00+01:00 | B11: 323.73819 | C11: 328.01041 | D11: 323.26349 | E11: 327.25089 | F11: 326.53326 | G11: 6758283 | H11: 0 | I11: 0
A12: 2016-09-01 00:00:00+01:00 | B12: 328.8649 | C12: 331.86209 | D12: 323.26349 | E12: 328.95981 | F12: 328.23843 | G12: 7624817 | H12: 0 | I12: 0
A13: 2016-09-02 00:00:00+01:00 | B13: 331.42819 | C13: 337.69409 | D13: 326.6813 | E13: 336.17511 | F13: 335.43793 | G13: 12133971 | H13: 0 | I13: 0
... A2527: 2026-08-17 00:00:00+01:00 | B2527: 382.89999 | C2527: 384.20001 | D2527: 371.79999 | E2527: 381.60001 | F2527: 381.60001 | G2527: 11650000 | H2527: 0 | I2527: 0

Sheet NG L
A1: Date | B1: Open | C1: High | D1: Low | E1: Close | F1: Adj Close | G1: Volume | H1: Dividends | I1: Stock Splits
A2: 2016-08-17 00:00:00+01:00 | B2: 1180.3632 | C2: 1185.8177 | D2: 1167.2723 | E2: 1167.2723 | F2: 1161.0312 | G2: 7237738 | H2: 0 | I2: 0
A3: 2016-08-18 00:00:00+01:00 | B3: 1172.7268 | C3: 1186.3632 | D3: 1171.0905 | E3: 1179.8177 | F3: 1173.5098 | G3: 5398129 | H3: 0 | I3: 0
A4: 2016-08-19 00:00:00+01:00 | B4: 1183.0905 | C4: 1186.5159 | D4: 1177.0741 | E4: 1178.7268 | F4: 1172.4246 | G4: 4519797 | H4: 0 | I4: 0
A5: 2016-08-22 00:00:00+01:00 | B5: 1175.9995 | C5: 1184.7268 | D5: 1174.3632 | E5: 1179.2722 | F5: 1172.9672 | G5: 4187474 | H5: 0 | I5: 0
A6: 2016-08-23 00:00:00+01:00 | B6: 1172.1813 | C6: 1185.8177 | D6: 1166.1813 | E6: 1173.8177 | F6: 1167.5416 | G6: 3509653 | H6: 0 | I6: 0
A7: 2016-08-24 00:00:00+01:00 | B7: 1167.2723 | C7: 1175.9995 | D7: 1157.4541 | E7: 1160.1813 | F7: 1153.9784 | G7: 4000164 | H7: 0 | I7: 0
A8: 2016-08-25 00:00:00+01:00 | B8: 1165.6359 | C8: 1173.8177 | D8: 1160.7268 | E8: 1172.7268 | F8: 1166.4567 | G8: 3308408 | H8: 0 | I8: 0
A9: 2016-08-26 00:00:00+01:00 | B9: 1173.2723 | C9: 1177.6359 | D9: 1165.6904 | E9: 1172.1813 | F9: 1165.9139 | G9: 3461344 | H9: 0 | I9: 0
A10: 2016-08-30 00:00:00+01:00 | B10: 1168.3632 | C10: 1171.0905 | D10: 1148.7268 | E10: 1148.7268 | F10: 1142.5851 | G10: 5432003 | H10: 0 | I10: 0
A11: 2016-08-31 00:00:00+01:00 | B11: 1145.4541 | C11: 1154.1813 | D11: 1141.6359 | E11: 1141.6359 | F11: 1135.5321 | G11: 8503467 | H11: 0 | I11: 0
A12: 2016-09-01 00:00:00+01:00 | B12: 1152.545 | C12: 1153.0905 | D12: 1133.9995 | E12: 1135.0905 | F12: 1129.0216 | G12: 6998352 | H12: 0 | I12: 0
A13: 2016-09-02 00:00:00+01:00 | B13: 1142.1814 | C13: 1172.7268 | D13: 1138.9086 | E13: 1167.8177 | F13: 1161.5739 | G13: 10149074 | H13: 0 | I13: 0
... A2527: 2026-08-17 00:00:00+01:00 | B2527: 1195.5 | C2527: 1201 | D2527: 1182 | E2527: 1189.5 | F2527: 1189.5 | G2527: 4083674 | H2527: 0 | I2527: 0

Sheet ULVR L
A1: Date | B1: Open | C1: High | D1: Low | E1: Close | F1: Adj Close | G1: Volume | H1: Dividends | I1: Stock Splits
A2: 2016-08-17 00:00:00+01:00 | B2: 3862.3428 | C2: 3886.4055 | D2: 3842.5579 | E2: 3865.0166 | F2: 3851.3667 | G2: 1516287 | H2: 0 | I2: 0
A3: 2016-08-18 00:00:00+01:00 | B3: 3877.8499 | C3: 3887.4751 | D3: 3836.6758 | E3: 3848.4399 | F3: 3834.8477 | G3: 1289492 | H3: 0 | I3: 0
A4: 2016-08-19 00:00:00+01:00 | B4: 3847.905 | C4: 3862.3428 | D4: 3831.8633 | E4: 3856.9956 | F4: 3843.3735 | G4: 1269538 | H4: 0 | I4: 0
A5: 2016-08-22 00:00:00+01:00 | B5: 3845.7661 | C5: 3870.8984 | D5: 3804.592 | E5: 3813.1477 | F5: 3799.6807 | G5: 1448876 | H5: 0 | I5: 0
A6: 2016-08-23 00:00:00+01:00 | B6: 3825.4465 | C6: 3851.1135 | D6: 3806.1963 | E6: 3810.4741 | F6: 3797.0161 | G6: 1083772 | H6: 0 | I6: 0
A7: 2016-08-24 00:00:00+01:00 | B7: 3790.6892 | C7: 3811.5437 | D7: 3760.2097 | E7: 3771.439 | F7: 3758.1187 | G7: 1652894 | H7: 0 | I7: 0
A8: 2016-08-25 00:00:00+01:00 | B8: 3776.2515 | C8: 3813.1477 | D8: 3755.9319 | E8: 3806.7312 | F8: 3793.2869 | G8: 1456280 | H8: 0 | I8: 0
A9: 2016-08-26 00:00:00+01:00 | B9: 3804.0574 | C9: 3820.0994 | D9: 3768.8745 | E9: 3816.8909 | F9: 3803.4097 | G9: 1188305 | H9: 0 | I9: 0
A10: 2016-08-30 00:00:00+01:00 | B10: 3836.1411 | C10: 3861.2734 | D10: 3806.7312 | E10: 3817.4255 | F10: 3803.9426 | G10: 1778822 | H10: 0 | I10: 0
A11: 2016-08-31 00:00:00+01:00 | B11: 3814.752 | C11: 3826.5161 | D11: 3762.8833 | E11: 3774.1125 | F11: 3760.7832 | G11: 2220923 | H11: 0 | I11: 0
A12: 2016-09-01 00:00:00+01:00 | B12: 3807.8005 | C12: 3815.8213 | D12: 3754.8623 | E12: 3772.5083 | F12: 3759.1848 | G12: 2612211 | H12: 0 | I12: 0
A13: 2016-09-02 00:00:00+01:00 | B13: 3785.8767 | C13: 3944.6909 | D13: 3778.9253 | E13: 3917.4199 | F13: 3903.5837 | G13: 4334946 | H13: 0 | I13: 0
... A2527: 2026-08-17 00:00:00+01:00 | B2527: 4552 | C2527: 4574 | D2527: 4496 | E2527: 4512.5 | F2527: 4512.5 | G2527: 2071184 | H2527: 0 | I2527: 0

Sheet VGOV L
A1: Date | B1: Open | C1: High | D1: Low | E1: Close | F1: Adj Close | G1: Volume | H1: Dividends | I1: Stock Splits | J1: Capital Gains
A2: 2016-08-17 00:00:00+01:00 | B2: 24.43 | C2: 24.453501 | D2: 24.3435 | E2: 24.385 | F2: 19.274956 | G2: 1897645 | H2: 0 | I2: 0 | J2: 0
A3: 2016-08-18 00:00:00+01:00 | B3: 24.434999 | C3: 24.475 | D3: 24.3351 | E3: 24.440001 | F3: 19.34059 | G3: 16912 | H3: 0.027956 | I3: 0 | J3: 0
A4: 2016-08-19 00:00:00+01:00 | B4: 24.440001 | C4: 24.4485 | D4: 24.25 | E4: 24.24 | F4: 19.182323 | G4: 72029 | H4: 0 | I4: 0 | J4: 0
A5: 2016-08-22 00:00:00+01:00 | B5: 24.34 | C5: 24.428499 | D5: 24.2985 | E5: 24.4025 | F5: 19.310919 | G5: 44091 | H5: 0 | I5: 0 | J5: 0
A6: 2016-08-23 00:00:00+01:00 | B6: 24.504999 | C6: 24.578501 | D6: 24.355101 | E6: 24.514999 | F6: 19.399939 | G6: 13211 | H6: 0 | I6: 0 | J6: 0
A7: 2016-08-24 00:00:00+01:00 | B7: 24.530001 | C7: 24.6035 | D7: 24.490101 | E7: 24.547501 | F7: 19.425667 | G7: 222890 | H7: 0 | I7: 0 | J7: 0
A8: 2016-08-25 00:00:00+01:00 | B8: 24.555 | C8: 24.578501 | D8: 24.5 | E8: 24.525 | F8: 19.407858 | G8: 96365 | H8: 0 | I8: 0 | J8: 0
A9: 2016-08-26 00:00:00+01:00 | B9: 24.52 | C9: 24.625 | D9: 24.4851 | E9: 24.58 | F9: 19.45138 | G9: 22581 | H9: 0 | I9: 0 | J9: 0
A10: 2016-08-30 00:00:00+01:00 | B10: 24.58 | C10: 24.655001 | D10: 24.4951 | E10: 24.5975 | F10: 19.465225 | G10: 7292 | H10: 0 | I10: 0 | J10: 0
A11: 2016-08-31 00:00:00+01:00 | B11: 24.555 | C11: 24.6485 | D11: 24.465099 | E11: 24.51 | F11: 19.39599 | G11: 252737 | H11: 0 | I11: 0 | J11: 0
A12: 2016-09-01 00:00:00+01:00 | B12: 24.370001 | C12: 24.4935 | D12: 24.3251 | E12: 24.477501 | F12: 19.370274 | G12: 20744 | H12: 0 | I12: 0 | J12: 0
A13: 2016-09-02 00:00:00+01:00 | B13: 24.43 | C13: 24.668501 | D13: 24.2885 | E13: 24.295 | F13: 19.22583 | G13: 43261 | H13: 0 | I13: 0 | J13: 0
... A2526: 2026-08-17 00:00:00+01:00 | B2526: 15.462 | C2526: 15.515 | D2526: 15.414 | E2526: 15.416 | F2526: 15.416 | G2526: 67312 | H2526: 0 | I2526: 0 | J2526: 0

Sheet SGLN L
A1: Date | B1: Open | C1: High | D1: Low | E1: Close | F1: Adj Close | G1: Volume | H1: Dividends | I1: Stock Splits
A2: 2016-08-17 00:00:00+01:00 | B2: 2033 | C2: 2043.2 | D2: 2032 | E2: 2042 | F2: 2042 | G2: 81728 | H2: 0 | I2: 0
A3: 2016-08-18 00:00:00+01:00 | B3: 2039.5 | C3: 2043.5601 | D3: 2020.826 | E3: 2025.75 | F3: 2025.75 | G3: 84743 | H3: 0 | I3: 0
A4: 2016-08-19 00:00:00+01:00 | B4: 2024.5 | C4: 2036.6 | D4: 2018.8199 | E4: 2030 | F4: 2030 | G4: 61190 | H4: 0 | I4: 0
A5: 2016-08-22 00:00:00+01:00 | B5: 2010.5 | C5: 2018.103 | D5: 2006.801 | E5: 2011 | F5: 2011 | G5: 50857 | H5: 0 | I5: 0
A6: 2016-08-23 00:00:00+01:00 | B6: 2012.5 | C6: 2012.5 | D6: 2002.48 | E6: 2003.5 | F6: 2003.5 | G6: 96277 | H6: 0 | I6: 0
A7: 2016-08-24 00:00:00+01:00 | B7: 2001.5 | C7: 2004.88 | D7: 1972.6 | E7: 1980 | F7: 1980 | G7: 2826701 | H7: 0 | I7: 0
A8: 2016-08-25 00:00:00+01:00 | B8: 1977.5 | C8: 1983.38 | D8: 1972.8 | E8: 1977.75 | F8: 1977.75 | G8: 60614 | H8: 0 | I8: 0
A9: 2016-08-26 00:00:00+01:00 | B9: 1977.5 | C9: 1996.514 | D9: 1975.796 | E9: 1990.75 | F9: 1990.75 | G9: 104636 | H9: 0 | I9: 0
A10: 2016-08-30 00:00:00+01:00 | B10: 1993.5 | C10: 1996.38 | D10: 1981.849 | E10: 1986.25 | F10: 1986.25 | G10: 76731 | H10: 0 | I10: 0
A11: 2016-08-31 00:00:00+01:00 | B11: 1979 | C11: 1979.7 | D11: 1967.4399 | E11: 1966 | F11: 1966 | G11: 191730 | H11: 0 | I11: 0
A12: 2016-09-01 00:00:00+01:00 | B12: 1962 | C12: 1963.1 | D12: 1939.937 | E12: 1947.75 | F12: 1947.75 | G12: 64612 | H12: 0 | I12: 0
A13: 2016-09-02 00:00:00+01:00 | B13: 1949.5 | C13: 1967.2 | D13: 1947.5 | E13: 1956.5 | F13: 1956.5 | G13: 75690 | H13: 0 | I13: 0
... A2527: 2026-08-17 00:00:00+01:00 | B2527: 6298 | C2527: 6334 | D2527: 6263 | E2527: 6328 | F2527: 6328 | G2527: 315404 | H2527: 0 | I2527: 0
